Workbook

Sheet Instructions
A1: SVDP Comprehensive Excel Workbook
A3: Purpose | B3: Excel-first decision-support model for donated-goods space optimization, goods flow, and procurement analysis.
A4: How to present | B4: Start with Executive_Dashboard, then Flow_Dashboard, then Slotting_Dashboard. Use Recommendations last.
A5: What is editable | B5: Only yellow cells in Controls and any estimated quantities in Slotting_Model if you receive better counts.
A6: Key data sources | B6: General Ledger, uploaded invoices, monthly result workbooks, warehouse layout redesigns, and rack sketch.
A7: Important note | B7: Qty_Held values are planning assumptions so the model can run now. Update later if the client provides exact inventory.
A20: Important | B20: Open this workbook in Excel desktop and save once so all formulas and charts recalculate and display cached values correctly.

Sheet Executive_Dashboard
A1: SVDP Donated Goods Space Optimization – Executive Dashboard
A3: Project objective: | B3: Optimize space utilization and goods flow through slotting, bin classification, and warehouse redesign.
A5: Total Spend | D5: Capacity Increase | G5: Water Orders | J5: Est. Water Savings
A6: =Project_KPIs!B4 | D6: =Project_KPIs!B10 | G6: =Project_KPIs!B8 | J6: =Project_KPIs!B13
A9: Before vs After | F9: Key Insights
A10: Metric | B10: Before | C10: After / Impact | F10: • Water ordering is highly repetitive, indicating a contract opportunity.
A11: Pallet Capacity | B11: =Warehouse_Capacity!B8 | C11: =Warehouse_Capacity!C8 | F11: • Warehouse redesign uses the 4 uploaded layout files; quantified net pallet gain is 251 positions.
A12: Capacity Change | B12: - | C12: =Warehouse_Capacity!D8 | F12: • GIK delivers the strongest capacity gain and should support high-flow items.
A13: Capacity Change % | B13: - | C13: =Warehouse_Capacity!E8 | F13: • Slotting recommendations prioritize usage, flow, quantity received, quantity held, and item type.
A14: Water Spend | B14: - | C14: =Project_KPIs!B7 | F14: • Final plan applies a capacity constraint so only top-ranked items use premium locations; remaining items are distributed across FOOD, GIK, GARAGE/KITCHEN, and ADDITIONS.
F16: • The final reallocation plan now uses one consistent hybrid location logic across all slotting sheets.
H17: Month | I17: Net Spend ($)
H18: 45566 | I18: 63380.44
H19: 45597 | I19: 87215.87
H20: 45627 | I20: 62474.12
H21: 45658 | I21: 3561.6
H22: 45689 | I22: 3561.6
H23: 45717 | I23: 155712.6
H24: 45748 | I24: 74243.13
H25: 45809 | I25: 40638.24
H26: 45839 | I26: 136090.8
H27: 45870 | I27: 37459.2
H28: 45901 | I28: 61717.1

Sheet Flow_Dashboard
A1: Goods Flow Dashboard
A3: Monthly goods-flow view showing inbound volume, usable output, and processing losses (waste + RTV) to support slotting decisions.
A5: Total Inbound lbs | D5: Net Usable lbs | G5: Water Orders | J5: Net Capacity Gain
A6: =Monthly_Flow!I8 | D6: =Monthly_Flow!J8 | G6: =Project_KPIs!B8 | J6: =Project_KPIs!B10
A10: Month | B10: TEFAP Lbs | C10: Regular Receipts Lbs | D10: Food Drives Lbs | E10: Truck Log Lbs | F10: Receiving Sheet Lbs | G10: RTV Lbs | H10: Garbage Out Lbs | I10: Total Inbound Lbs | J10: Net Usable Lbs | L10: Month | M10: Inbound | N10: Net Usable | O10: Yield % | Q10: Month | R10: RTV | S10: Garbage
A11: Oct-2025 | B11: 1764 | C11: 89891 | D11: 0 | E11: 23795 | F11: 497495 | G11: 4728 | H11: 66380 | I11: 91655 | J11: 20547 | L11: =A11 | M11: =I11 | N11: =J11 | O11: =IFERROR(N11/M11,0) | Q11: =A11 | R11: =G11 | S11: =H11
A12: Nov-2025 | B12: 5890 | C12: 70232 | D12: 82211 | E12: 31749 | F12: 497066 | G12: 0 | H12: 43960 | I12: 158333 | J12: 114373 | L12: =A12 | M12: =I12 | N12: =J12 | O12: =IFERROR(N12/M12,0) | Q12: =A12 | R12: =G12 | S12: =H12
A13: Dec-2025 | B13: 10034 | C13: 60625 | D13: 60207 | E13: 24957 | F13: 435128 | G13: 0 | H13: 34980 | I13: 130866 | J13: 95886 | L13: =A13 | M13: =I13 | N13: =J13 | O13: =IFERROR(N13/M13,0) | Q13: =A13 | R13: =G13 | S13: =H13
A14: Jan-2026 | B14: 13180 | C14: 438120 | D14: 15600 | E14: 87625 | F14: 438120 | G14: 8178 | H14: 38600 | I14: 466900 | J14: 420122 | L14: =A14 | M14: =I14 | N14: =J14 | O14: =IFERROR(N14/M14,0) | Q14: =A14 | R14: =G14 | S14: =H14
W20: How to read this dashboard
W21: • Inbound vs Net Usable shows how much material actually becomes usable inventory.
W22: • Yield % indicates the efficiency of processing and handling.
W23: • RTV + Garbage highlights where losses reduce usable output.

Sheet Slotting_Dashboard
A1: Slotting & Goods-Flow Dashboard
A3: Dashboard shows current vs hybrid plan. Distribution inside each bucket now follows score rank, not row order.
A5: Items evaluated | D5: Moves / re-slots | G5: Premium items | J5: Reserve items
A6: =COUNTA(Slotting_Model!A4:A18) | D6: =COUNTIF(Slotting_Model!AJ4:AJ18,"<>Keep in place") | G6: =COUNTIF(Slotting_Model!AH4:AH18,"Premium") | J6: =COUNTIF(Slotting_Model!AH4:AH18,"Reserve")
A10: Item | B10: Current | C10: Hybrid_Location | D10: Score | E10: Hybrid_Reason | Q10: How to read this dashboard | Z10: How to read this dashboard
A11: =Slotting_Model!A4 | B11: =Slotting_Model!J4 | C11: =Slotting_Model!AO4 | D11: =Slotting_Model!X4 | E11: =Slotting_Model!AP4 | Q11: • Current = assumed existing location. | Z11: • Current shows the assumed existing location.
A12: =Slotting_Model!A5 | B12: =Slotting_Model!J5 | C12: =Slotting_Model!AO5 | D12: =Slotting_Model!X5 | E12: =Slotting_Model!AP5 | Q12: • Hybrid_Location = final practical location using your chosen ranking sequence. | Z12: • Depth-Optimized Plan shows the implementable location after capacity and 1/2/3 position balancing.
A13: =Slotting_Model!A6 | B13: =Slotting_Model!J6 | C13: =Slotting_Model!AO6 | D13: =Slotting_Model!X6 | E13: =Slotting_Model!AP6 | Q13: • The sequence used is A1, B1, C1, A2, B2, A3, B3, C2, C3. | Z13: • Premium items are no longer all assigned to the same A-front position.
A14: =Slotting_Model!A7 | B14: =Slotting_Model!J7 | C14: =Slotting_Model!AO7 | D14: =Slotting_Model!X7 | E14: =Slotting_Model!AP7 | Q14: • This logic is now used consistently in Slotting_Model, Storage_Reallocation_Plan, and Slotting_Dashboard. | Z14: • The 1 / 2 / 3 chart confirms the model is distributing storage positions more realistically.
A15: =Slotting_Model!A8 | B15: =Slotting_Model!J8 | C15: =Slotting_Model!AO8 | D15: =Slotting_Model!X8 | E15: =Slotting_Model!AP8
A16: =Slotting_Model!A9 | B16: =Slotting_Model!J9 | C16: =Slotting_Model!AO9 | D16: =Slotting_Model!X9 | E16: =Slotting_Model!AP9
A17: =Slotting_Model!A10 | B17: =Slotting_Model!J10 | C17: =Slotting_Model!AO10 | D17: =Slotting_Model!X10 | E17: =Slotting_Model!AP10
A18: =Slotting_Model!A11 | B18: =Slotting_Model!J11 | C18: =Slotting_Model!AO11 | D18: =Slotting_Model!X11 | E18: =Slotting_Model!AP11 | J18: Hybrid Logic Check
A19: =Slotting_Model!A12 | B19: =Slotting_Model!J12 | C19: =Slotting_Model!AO12 | D19: =Slotting_Model!X12 | E19: =Slotting_Model!AP12 | J19: Items are now ordered within each bucket by score rank.
A20: =Slotting_Model!A13 | B20: =Slotting_Model!J13 | C20: =Slotting_Model!AO13 | D20: =Slotting_Model!X13 | E20: =Slotting_Model!AP13 | J20: Higher-scoring Premium items take earlier hybrid positions.
A21: =Slotting_Model!A14 | B21: =Slotting_Model!J14 | C21: =Slotting_Model!AO14 | D21: =Slotting_Model!X14 | E21: =Slotting_Model!AP14 | J21: This removes dependence on row order.
A22: =Slotting_Model!A15 | B22: =Slotting_Model!J15 | C22: =Slotting_Model!AO15 | D22: =Slotting_Model!X15 | E22: =Slotting_Model!AP15
A23: =Slotting_Model!A16 | B23: =Slotting_Model!J16 | C23: =Slotting_Model!AO16 | D23: =Slotting_Model!X16 | E23: =Slotting_Model!AP16
A24: =Slotting_Model!A17 | B24: =Slotting_Model!J17 | C24: =Slotting_Model!AO17 | D24: =Slotting_Model!X17 | E24: =Slotting_Model!AP17
A25: =Slotting_Model!A18 | B25: =Slotting_Model!J18 | C25: =Slotting_Model!AO18 | D25: =Slotting_Model!X18 | E25: =Slotting_Model!AP18
A26: Capacity Bucket | B26: Count | G26: Capacity Bucket | H26: Count | J26: Preferred Area | K26: Count | M26: Pattern | N26: Count | Q26: Area | R26: Count
A27: Premium | B27: =COUNTIF(Slotting_Model!AH4:AH18,"Premium") | G27: Premium | H27: =COUNTIF(Slotting_Model!AH4:AH18,"Premium") | J27: GIK | K27: =COUNTIF(Slotting_Model!AG4:AG18,"GIK") | M27: A1 | N27: =COUNTIF(Slotting_Model!AO4:AO18,"*-A1-*") | Q27: GIK | R27: =COUNTIF(Slotting_Model!AG4:AG18,"GIK")
A28: Standard | B28: =COUNTIF(Slotting_Model!AH4:AH18,"Standard") | G28: Standard | H28: =COUNTIF(Slotting_Model!AH4:AH18,"Standard") | J28: FOOD | K28: =COUNTIF(Slotting_Model!AG4:AG18,"FOOD") | M28: B1 | N28: =COUNTIF(Slotting_Model!AO4:AO18,"*-B1-*") | P28: How to read this dashboard | Q28: FOOD | R28: =COUNTIF(Slotting_Model!AG4:AG18,"FOOD")
A29: Reserve | B29: =COUNTIF(Slotting_Model!AH4:AH18,"Reserve") | G29: Reserve | H29: =COUNTIF(Slotting_Model!AH4:AH18,"Reserve") | J29: GARAGE/KITCHEN | K29: =COUNTIF(Slotting_Model!AG4:AG18,"GARAGE/KITCHEN") | M29: C1 | N29: =COUNTIF(Slotting_Model!AO4:AO18,"*-C1-*") | P29: • Current shows where the item is assumed to be today. | Q29: GARAGE/KITCHEN | R29: =COUNTIF(Slotting_Model!AG4:AG18,"GARAGE/KITCHEN")
J30: ADDITIONS | K30: =COUNTIF(Slotting_Model!AG4:AG18,"ADDITIONS") | M30: A2 | N30: =COUNTIF(Slotting_Model!AO4:AO18,"*-A2-*") | P30: • Practical Plan shows the implementable location after applying capacity constraints. | Q30: ADDITIONS | R30: =COUNTIF(Slotting_Model!AG4:AG18,"ADDITIONS")
A31: Chart Check | M31: Other | N31: =COUNTA(Slotting_Model!AO4:AO18)-SUM(N27:N30) | P31: • Capacity Bucket shows which items get premium vs standard vs reserve storage.
A32: • Bar chart now uses the final Storage Priority Score column. | P32: • Preferred Area links each item to the most suitable warehouse area from the 4 uploaded layouts.
A33: • Pie chart now counts recommended A/B/C levels from the final model.
A34: • Dashboard table uses Current Location, Recommended Location, Score, and Reason from the updated Slotting_Model. | P34: • Capacity distribution chart now uses Premium / Standard / Reserve from the capacity-constrained plan.

Sheet Project_KPIs
A1: Project KPIs
A3: Metric | B3: Value | C3: Interpretation | D3: Source
A4: Total Spend ($) | B4: =SUM(Clean_Transactions!H:H) | C4: Spend observed in cleaned transaction ledger | D4: Clean_Transactions
A5: Food Spend ($) | B5: =SUMIF(Clean_Transactions!D:D,"Food",Clean_Transactions!H:H) | C5: Food procurement exposure | D5: Clean_Transactions
A6: Meat Spend ($) | B6: =SUMIF(Clean_Transactions!D:D,"Meat",Clean_Transactions!H:H) | C6: Protein / meat procurement exposure | D6: Clean_Transactions
A7: Water Spend ($) | B7: =SUM(Water_Unique!G4:G18) | C7: Validated repetitive water spend | D7: Water_Unique
A8: Unique Water Orders | B8: =COUNTA(Water_Unique!B4:B18) | C8: Deduplicated Niagara order count | D8: Water_Unique
A9: Unique Suppliers | B9: =SUMPRODUCT((Clean_Transactions!C4:C200<>"")/COUNTIF(Clean_Transactions!C4:C200,Clean_Transactions!C4:C200&"")) | C9: Supplier breadth in cleaned data | D9: Clean_Transactions
A10: Capacity Increase (Pallets) | B10: =Warehouse_Capacity!D8 | C10: Net pallet increase from redesign areas | D10: Warehouse_Capacity
A11: Capacity Increase (%) | B11: =Warehouse_Capacity!E8 | C11: Net pallet increase as % of prior capacity | D11: Warehouse_Capacity
A12: Net Usable Inbound (lbs) | B12: =Monthly_Flow!J8 | C12: Usable pounds from uploaded monthly results | D12: Monthly_Flow
A13: Estimated Water Savings @8% | B13: =B7*8% | C13: Illustrative savings if contract pricing improves | D13: Water_Unique

Sheet Controls
A1: Model Controls
A3: Input | B3: Value | C3: Explanation / Criteria
A4: Usage Weight | B4: 2 | C4: Usage Weight = 2 because demand/usage velocity is one of the strongest drivers of slotting. Fast-moving items should be easier to access to reduce travel and picking time.
A5: Flow Weight | B5: 2 | C5: Flow Weight = 2 because internal goods flow is equally critical. Items that move through inbound, staging, storage, and outbound more often should be placed to reduce congestion.
A6: Qty Received Weight | B6: 1.2 | C6: Qty Received Weight = 1.2 because large inbound batches can create staging pressure and should influence where items are slotted.
A7: Qty Held Weight | B7: 0.8 | C7: Qty Held Weight = 0.8 because on-hand stock matters, but less than usage and flow when assigning priority storage.
A8: Item Type Weight | B8: 1 | C8: Item Type Weight = 1 to reflect handling needs, such as bulk, heavy, fragile, or food-specific storage requirements.
A9: Freq Weight | B9: 1 | C9: Frequency Weight = 1 because inbound/outbound frequency helps refine movement intensity without overpowering the main usage and flow factors.
A10: A-Level Threshold | B10: 22 | C10: A-Level Threshold = 22 means only the highest-priority items qualify for premium lower/front storage locations.
A11: B-Level Threshold | B11: 16 | C11: B-Level Threshold = 16 means medium-priority items are placed in intermediate locations. Items below this generally move to C-level or deeper storage.
A12: Bulk Lower-Level Cutoff | B12: 1000 | C12: Bulk Lower-Level Cutoff = 1000 means any bulk item with more than 1,000 units held should be forced to a lower level for safety, handling, and replenishment efficiency.
A15: Cube Measurement Controls
A17: Input | B17: Value | C17: Explanation / Criteria
A18: Min Cube Height (ft) | B18: 5.25 | C18: Minimum observed cube height based on site measurement: 5'3".
A19: Max Cube Height (ft) | B19: 6.08 | C19: Maximum observed cube height based on site measurement: 6'1".
A20: Cube Width (in) | B20: 40 | C20: Observed cube width.
A21: Cube Depth (in) | B21: 48 | C21: Observed cube depth.
A22: Default Cube Height (ft) | B22: 5.67 | C22: Average working height used for volume calculations when a specific height is not assigned.
A24: Fresh Food Max Days | B24: 3 | C24: Fresh food should move within 3 days; use high flow and front-access recommendations where applicable.

Sheet Capacity_Constraints
A1: Capacity-Constrained Allocation Logic
A3: Constraint | B3: Value | C3: How Used
A4: Premium item slots | B4: 5 | C4: Only the top 5 ranked items can use premium A-level/front locations.
A5: Standard item slots | B5: 5 | C5: Next 5 ranked items are pushed to standard B-level/mid-access locations.
A6: Reserve item slots | B6: 5 | C6: Remaining items are routed to reserve/support storage.
A7: GIK role | B7: High-flow bulk zone | C7: Primary zone for water, bulk pantry, and fast protein items.
A8: FOOD role | B8: Primary food zone | C8: Main zone for staple and entrée food items.
A9: GARAGE/KITCHEN role | B9: Reserve / support zone | C9: Used for medium/low-priority reserve and support storage.
A10: ADDITIONS role | B10: Overflow bulk support | C10: Used qualitatively to support push-back overflow for very large items.
A12: Depth Optimization Rule | B12: Enabled | C12: Within each capacity bucket, items are distributed across 1 / 2 / 3 based on rank so premium items do not all go to the same front-most slot.

Sheet Field_Notes
A1: Field Notes and Operating Assumptions
A3: Note | B3: How Applied in Model
A4: Peanut butter comes in bulk around 4 times per week (1 truckload). | B4: Peanut Butter was reclassified as Bulk and its inbound/outbound frequency was increased to 4x/Week to reflect higher movement.
A5: Fresh food stays in the warehouse at most 3 days. | B5: Fresh / time-sensitive items were treated as high-flow items so they are recommended to fast-access storage.
A6: 26 pallets come to warehouse every week (not fully confirmed). | B6: This was documented as an operational note, but not used as a hard quantitative rule because it is not fully confirmed.
A7: Core slotting factors: usage rate, item type, quantity received, quantity held. | B7: These remain the core drivers in the slotting score, together with goods flow and cube-fit validation.

Sheet Storage_Reallocation_Plan
A1: Practical Storage Reallocation Plan (Score-Based Hybrid Logic)
A3: Item | B3: Current_Location | C3: Model_Ideal_Location | D3: Hybrid_Location | E3: Preferred_Area | F3: Priority_Rank | G3: Bucket | H3: Action | I3: Reason
A4: =Slotting_Model!A4 | B4: =Slotting_Model!J4 | C4: =Slotting_Model!AB4 | D4: =Slotting_Model!AO4 | E4: =Slotting_Model!AG4 | F4: =Slotting_Model!AF4 | G4: =Slotting_Model!AH4 | H4: =IF(B4=D4,"Keep in place","Move using hybrid ranking plan") | I4: =Slotting_Model!AP4
A5: =Slotting_Model!A5 | B5: =Slotting_Model!J5 | C5: =Slotting_Model!AB5 | D5: =Slotting_Model!AO5 | E5: =Slotting_Model!AG5 | F5: =Slotting_Model!AF5 | G5: =Slotting_Model!AH5 | H5: =IF(B5=D5,"Keep in place","Move using hybrid ranking plan") | I5: =Slotting_Model!AP5
A6: =Slotting_Model!A6 | B6: =Slotting_Model!J6 | C6: =Slotting_Model!AB6 | D6: =Slotting_Model!AO6 | E6: =Slotting_Model!AG6 | F6: =Slotting_Model!AF6 | G6: =Slotting_Model!AH6 | H6: =IF(B6=D6,"Keep in place","Move using hybrid ranking plan") | I6: =Slotting_Model!AP6
A7: =Slotting_Model!A7 | B7: =Slotting_Model!J7 | C7: =Slotting_Model!AB7 | D7: =Slotting_Model!AO7 | E7: =Slotting_Model!AG7 | F7: =Slotting_Model!AF7 | G7: =Slotting_Model!AH7 | H7: =IF(B7=D7,"Keep in place","Move using hybrid ranking plan") | I7: =Slotting_Model!AP7
A8: =Slotting_Model!A8 | B8: =Slotting_Model!J8 | C8: =Slotting_Model!AB8 | D8: =Slotting_Model!AO8 | E8: =Slotting_Model!AG8 | F8: =Slotting_Model!AF8 | G8: =Slotting_Model!AH8 | H8: =IF(B8=D8,"Keep in place","Move using hybrid ranking plan") | I8: =Slotting_Model!AP8
A9: =Slotting_Model!A9 | B9: =Slotting_Model!J9 | C9: =Slotting_Model!AB9 | D9: =Slotting_Model!AO9 | E9: =Slotting_Model!AG9 | F9: =Slotting_Model!AF9 | G9: =Slotting_Model!AH9 | H9: =IF(B9=D9,"Keep in place","Move using hybrid ranking plan") | I9: =Slotting_Model!AP9
A10: =Slotting_Model!A10 | B10: =Slotting_Model!J10 | C10: =Slotting_Model!AB10 | D10: =Slotting_Model!AO10 | E10: =Slotting_Model!AG10 | F10: =Slotting_Model!AF10 | G10: =Slotting_Model!AH10 | H10: =IF(B10=D10,"Keep in place","Move using hybrid ranking plan") | I10: =Slotting_Model!AP10
A11: =Slotting_Model!A11 | B11: =Slotting_Model!J11 | C11: =Slotting_Model!AB11 | D11: =Slotting_Model!AO11 | E11: =Slotting_Model!AG11 | F11: =Slotting_Model!AF11 | G11: =Slotting_Model!AH11 | H11: =IF(B11=D11,"Keep in place","Move using hybrid ranking plan") | I11: =Slotting_Model!AP11
A12: =Slotting_Model!A12 | B12: =Slotting_Model!J12 | C12: =Slotting_Model!AB12 | D12: =Slotting_Model!AO12 | E12: =Slotting_Model!AG12 | F12: =Slotting_Model!AF12 | G12: =Slotting_Model!AH12 | H12: =IF(B12=D12,"Keep in place","Move using hybrid ranking plan") | I12: =Slotting_Model!AP12
A13: =Slotting_Model!A13 | B13: =Slotting_Model!J13 | C13: =Slotting_Model!AB13 | D13: =Slotting_Model!AO13 | E13: =Slotting_Model!AG13 | F13: =Slotting_Model!AF13 | G13: =Slotting_Model!AH13 | H13: =IF(B13=D13,"Keep in place","Move using hybrid ranking plan") | I13: =Slotting_Model!AP13
A14: =Slotting_Model!A14 | B14: =Slotting_Model!J14 | C14: =Slotting_Model!AB14 | D14: =Slotting_Model!AO14 | E14: =Slotting_Model!AG14 | F14: =Slotting_Model!AF14 | G14: =Slotting_Model!AH14 | H14: =IF(B14=D14,"Keep in place","Move using hybrid ranking plan") | I14: =Slotting_Model!AP14
A15: =Slotting_Model!A15 | B15: =Slotting_Model!J15 | C15: =Slotting_Model!AB15 | D15: =Slotting_Model!AO15 | E15: =Slotting_Model!AG15 | F15: =Slotting_Model!AF15 | G15: =Slotting_Model!AH15 | H15: =IF(B15=D15,"Keep in place","Move using hybrid ranking plan") | I15: =Slotting_Model!AP15
... A18: =Slotting_Model!A18 | B18: =Slotting_Model!J18 | C18: =Slotting_Model!AB18 | D18: =Slotting_Model!AO18 | E18: =Slotting_Model!AG18 | F18: =Slotting_Model!AF18 | G18: =Slotting_Model!AH18 | H18: =IF(B18=D18,"Keep in place","Move using hybrid ranking plan") | I18: =Slotting_Model!AP18
A21: How this plan works
A22: • Premium A-level/front slots are limited to the top-ranked items only.
A23: • GIK is used for bulk/high-flow items because it has the strongest quantified expansion.
A24: • FOOD is used for core staple food items and high-use pantry items.
A25: • GARAGE/KITCHEN is used as reserve/support storage for medium and lower-priority items.
A26: • ADDITIONS is used as overflow bulk support because the drawing supports push-back expansion but does not provide a stated pallet total.

Sheet Category_Summary
A1: Category Summary
A3: Category | B3: Txn Count | C3: Net Spend ($) | D3: Spend Share | E3: Avg Ticket ($)
A4: Food | B4: =COUNTIF(Clean_Transactions!D:D,A4) | C4: =SUMIF(Clean_Transactions!D:D,A4,Clean_Transactions!H:H) | D4: =IF($C$7=0,0,C4/$C$7) | E4: =IF(B4=0,0,C4/B4)
A5: Meat | B5: =COUNTIF(Clean_Transactions!D:D,A5) | C5: =SUMIF(Clean_Transactions!D:D,A5,Clean_Transactions!H:H) | D5: =IF($C$7=0,0,C5/$C$7) | E5: =IF(B5=0,0,C5/B5)
A6: Water | B6: =COUNTIF(Clean_Transactions!D:D,A6) | C6: =SUMIF(Clean_Transactions!D:D,A6,Clean_Transactions!H:H) | D6: =IF($C$7=0,0,C6/$C$7) | E6: =IF(B6=0,0,C6/B6)
A7: Total | B7: =SUM(B4:B6) | C7: =SUM(C4:C6)

Sheet Vendor_Summary
A1: Vendor Summary
A3: Supplier | B3: Txn Count | C3: Net Spend ($) | D3: Spend Share | E3: Category Mix
A4: NIAGARA BOTTLING, LLC | B4: =COUNTIF(Clean_Transactions!C:C,A4) | C4: =SUMIF(Clean_Transactions!C:C,A4,Clean_Transactions!H:H) | D4: =IF($C$10=0,0,C4/$C$10) | E4: Water
A5: STAR FOODS INC. | B5: =COUNTIF(Clean_Transactions!C:C,A5) | C5: =SUMIF(Clean_Transactions!C:C,A5,Clean_Transactions!H:H) | D5: =IF($C$10=0,0,C5/$C$10) | E5: Food
A6: GLOBAL FOODS INC. | B6: =COUNTIF(Clean_Transactions!C:C,A6) | C6: =SUMIF(Clean_Transactions!C:C,A6,Clean_Transactions!H:H) | D6: =IF($C$10=0,0,C6/$C$10) | E6: Food, Meat
A7: CIS, LLC | B7: =COUNTIF(Clean_Transactions!C:C,A7) | C7: =SUMIF(Clean_Transactions!C:C,A7,Clean_Transactions!H:H) | D7: =IF($C$10=0,0,C7/$C$10) | E7: Food
A8: Utah Beef Producers LLC | B8: =COUNTIF(Clean_Transactions!C:C,A8) | C8: =SUMIF(Clean_Transactions!C:C,A8,Clean_Transactions!H:H) | D8: =IF($C$10=0,0,C8/$C$10) | E8: Meat
A9: Unknown | B9: =COUNTIF(Clean_Transactions!C:C,A9) | C9: =SUMIF(Clean_Transactions!C:C,A9,Clean_Transactions!H:H) | D9: =IF($C$10=0,0,C9/$C$10) | E9: Food / Water
A10: Total | B10: =SUM(B4:B9) | C10: =SUM(C4:C9)

Sheet Monthly_Flow
A1: Monthly Goods Flow
A3: Month | B3: TEFAP Lbs | C3: Regular Receipts Lbs | D3: Food Drives Lbs | E3: Truck Log Lbs | F3: Receiving Sheet Lbs | G3: RTV Lbs | H3: Garbage Out Lbs | I3: Total Inbound Lbs | J3: Net Usable Lbs
A4: Oct-2025 | B4: 1764 | C4: 89891 | D4: 0 | E4: 23795 | F4: 497495 | G4: 4728 | H4: 66380 | I4: 91655 | J4: 20547
A5: Nov-2025 | B5: 5890 | C5: 70232 | D5: 82211 | E5: 31749 | F5: 497066 | G5: 0 | H5: 43960 | I5: 158333 | J5: 114373
A6: Dec-2025 | B6: 10034 | C6: 60625 | D6: 60207 | E6: 24957 | F6: 435128 | G6: 0 | H6: 34980 | I6: 130866 | J6: 95886
A7: Jan-2026 | B7: 13180 | C7: 438120 | D7: 15600 | E7: 87625 | F7: 438120 | G7: 8178 | H7: 38600 | I7: 466900 | J7: 420122
A8: Total | B8: =SUM(B4:B7) | C8: =SUM(C4:C7) | D8: =SUM(D4:D7) | E8: =SUM(E4:E7) | F8: =SUM(F4:F7) | G8: =SUM(G4:G7) | H8: =SUM(H4:H7) | I8: =SUM(I4:I7) | J8: =SUM(J4:J7)

Sheet Warehouse_Capacity
A1: Warehouse Capacity and Layout Integration (4 Layout Files)
A3: Layout Area | B3: Before Pallets | C3: After Pallets | D3: Increase | E3: % Change | F3: How Used in Project
A4: GIK | B4: 282 | C4: 424 | D4: =C4-B4 | E4: =IF(B4=0,0,D4/B4) | F4: Used as the primary high-flow expansion zone from the GIK layout.
A5: FOOD | B5: 156 | C5: 214 | D5: =C5-B5 | E5: =IF(B5=0,0,D5/B5) | F5: Used for food storage redesign with 4-deep push-back plus selective rack.
A6: GARAGE/KITCHEN | B6: 243 | C6: 294 | D6: =C6-B6 | E6: =IF(B6=0,0,D6/B6) | F6: Combined from the Garage/Kitchen layout: garage gains capacity while kitchen trades off capacity for security and flow.
A7: ADDITIONS | F7: Used qualitatively to support the push-back expansion concept and flow logic; pallet counts were not stated on the drawing.
A8: Total Quantified | B8: =SUM(B4:B7) | C8: =SUM(C4:C7) | D8: =SUM(D4:D7) | E8: =IF(B8=0,0,D8/B8) | F8: Quantified total from GIK, FOOD, and GARAGE/KITCHEN. ADDITIONS is included as a layout input, not a quantified pallet count.

Sheet Layout_Integration
A1: Layout Integration Summary
A3: Layout File | B3: How It Was Used | C3: Quantified Impact
A4: GIK | B4: Used as the main high-flow redesign zone and capacity expansion area. | C4: +142 pallets
A5: FOOD | B5: Used for food storage redesign with push-back and selective rack. | C5: +58 pallets
A6: GARAGE/KITCHEN | B6: Used as a combined redesign source; garage gains capacity while kitchen trades off capacity for security and flow. | C6: +51 pallets net
A7: ADDITIONS | B7: Used qualitatively to support the push-back expansion concept and flow logic. | C7: Qualitative only
A10: Note | B10: The workbook now explicitly uses all 4 uploaded layouts. Quantified totals use GIK, FOOD, and GARAGE/KITCHEN because the ADDITIONS drawing did not state pallet counts.

Sheet Cube_Measurements
A1: Cube Measurements and Utilization Logic
A3: Measured Dimension | B3: Value | C3: How Used in Model
A4: Height range | B4: 5'3" to 6'1" | C4: Used to justify the average working cube height in the slotting model.
A5: Width | B5: 40" | C5: Used directly in cube volume calculation.
A6: Depth | B6: 48" | C6: Used directly in cube volume calculation.
A7: Average working height | B7: 5.67 ft | C7: Used for default cube-volume calculations across storage locations.
A8: Approx. cube volume range | B8: 69.9 to 81.0 ft³ | C8: Used to validate physical feasibility and cube utilization.
A11: Model Rule | B11: Priority-based + Fit-based | C11: Recommended storage now depends on both business priority (usage, flow, quantity) and physical fit within the cube.

Sheet Location_Map
A1: Rack Location Map (Final Corrected)
A3: Level | B3: Bay 1 | C3: Bay 2 | D3: Bay 3 | E3: Cube_Height_ft | F3: Cube_Width_in | G3: Cube_Depth_in | H3: Cube_Volume_ft3 | I3: Priority_Rule
A4: A | B4: A1-Front | C4: A2-Middle | D4: A3-Back | E4: =Controls!$B$22 | F4: =Controls!$B$20 | G4: =Controls!$B$21 | H4: =ROUND(E4*(F4/12)*(G4/12),2) | I4: High-priority / fast-access / heavier items
A5: B | B5: B1-Front | C5: B2-Middle | D5: B3-Back | E5: =Controls!$B$22 | F5: =Controls!$B$20 | G5: =Controls!$B$21 | H5: =ROUND(E5*(F5/12)*(G5/12),2) | I5: Medium-priority items
A6: C | B6: C1-Front | C6: C2-Middle | D6: C3-Back | E6: =Controls!$B$22 | F6: =Controls!$B$20 | G6: =Controls!$B$21 | H6: =ROUND(E6*(F6/12)*(G6/12),2) | I6: Low-priority / reserve / overflow
A8: Location Logic
A9: A-level = High-priority / fast-access / heavier items
A10: B-level = Medium-priority / standard access
A11: C-level = Low-priority / reserve / overflow
A12: Front = fastest access, Middle = balanced access, Back = reserve / deeper storage

Sheet Lookup_Tables
A1: Lookup Tables | G1: Item Type Volume Assumptions | L1: Preferred Area Map
A3: Item Type | B3: Weight | D3: Frequency | E3: Score | G3: Item_Type | H3: Required_Volume_ft3 | I3: Fit Rule | J3: Rationale | L3: Item | M3: Preferred_Area | N3: Why
A4: Bulk | B4: 5 | D4: Daily | E4: 5 | G4: Bulk | H4: 72 | I4: Needs lower level if held qty is high | J4: Bulk items like water use more cube space and are heavier. | L4: Water | M4: GIK | N4: High-volume bulk, strong fit for lower-level high-flow expansion zone.
A5: Food | B5: 4 | D5: Weekly | E5: 4 | G5: Food | H5: 35 | I5: Standard cube fit | J5: Most dry/canned food items fit within a standard cube. | L5: Peanut Butter | M5: GIK | N5: Bulk-like pantry staple with high inbound frequency.
A6: Meat | B6: 4 | D6: Biweekly | E6: 3 | G6: Meat | H6: 48 | I6: Cold-chain / handling sensitive | J6: Protein/meat items need more buffer and handling allowance. | L6: Chicken Leg Quarters | M6: GIK | N6: High-flow protein item needing fast access.
A7: Fragile | B7: 3 | D7: 4x/Week | E7: 4.5 | G7: Fragile | H7: 28 | I7: Avoid deep/back where possible | J7: Fragile items should not be forced into tight/deep locations. | L7: Ground Beef | M7: ADDITIONS | N7: Very high volume; use overflow push-back concept supported by additions layout.
A8: Other | B8: 3 | D8: Biweekly | E8: 3 | L8: Tuna | M8: FOOD | N8: Fast-moving food staple; should stay in primary food zone.
D9: Weekly | E9: 4 | L9: Rice | M9: FOOD | N9: Core staple suited to food zone.
D10: Monthly | E10: 2 | L10: Black Beans | M10: FOOD | N10: Core staple suited to food zone.
D11: Ad Hoc | E11: 1 | L11: Pasta Sauce | M11: FOOD | N11: Food zone standard-access item.
L12: Oats | M12: GARAGE/KITCHEN | N12: Medium-priority food; can use reserve/support storage.
L13: Pancake Mix | M13: GARAGE/KITCHEN | N13: Medium-priority food; can use support storage.
L14: Peaches | M14: GARAGE/KITCHEN | N14: Lower-priority reserve/support placement.
L15: Chili - Beef | M15: FOOD | N15: High-demand food entrée item.
L16: Mixed Vegetables | M16: GARAGE/KITCHEN | N16: Reserve/support storage is acceptable.
L17: Green Beans | M17: FOOD | N17: Food zone staple item.
L18: Macaroni in Tomato Sauce | M18: FOOD | N18: High-usage entrée item in primary food area.

Sheet Slotting_Model
A1: Slotting Model (Hybrid Logic Applied)
A2: Hybrid ranking order used in this workbook: A1 → B1 → C1 → A2 → B2 → A3 → B3 → C2 → C3
A3: Item | B3: Category | C3: Item_Type | D3: Usage_Rate | E3: Qty_Received | F3: Qty_Held | G3: Flow_Priority | H3: Inbound_Freq | I3: Outbound_Freq | J3: Current_Location | K3: Cube_Height_ft | L3: Cube_Width_in | M3: Cube_Depth_in | N3: Cube_Volume_ft3 | O3: Item_Required_Volume_ft3 | P3: Fit_Check | Q3: Cube_Utilization_% | R3: Prelim_Recommendation | S3: Qty_Received_Score | T3: Qty_Held_Score | U3: ItemType_Weight | V3: Inbound_Score | W3: Outbound_Score | X3: Storage_Priority_Score | Y3: Recommended_Level | Z3: Recommended_Bay | AA3: Recommended_Depth | AB3: Final_Recommended_Location | AC3: Reason | AD3: Bulk_Flag | AE3: Model_Note | AF3: Priority_Rank | AG3: Preferred_Area | AH3: Capacity_Bucket | AI3: Capacity_Constrained_Location | AJ3: Implementation_Action | AK3: Bucket_Rank_By_Score | AL3: Depth_Optimized_Location | AM3: Depth_Optimization_Note | AN3: Hybrid_Order_Index | AO3: Hybrid_Location | AP3: Hybrid_Reason
A4: Water | B4: Water | C4: Bulk | D4: 5 | E4: 960 | F4: 1500 | G4: 5 | H4: Weekly | I4: Daily | J4: B2-Back | K4: =Controls!$B$22 | L4: =Controls!$B$20 | M4: =Controls!$B$21 | N4: =ROUND(K4*(L4/12)*(M4/12),2) | O4: =IFERROR(VLOOKUP(C4,Lookup_Tables!$G$4:$H$7,2,FALSE),35) | P4: =IF(O4<=N4,"Fits","Review") | Q4: =ROUND(O4/N4,3) | R4: =Y4&Z4&"-"&AA4 | S4: =IF(E4>=1000,5,IF(E4>=500,4,IF(E4>=250,3,IF(E4>=100,2,1)))) | T4: =IF(F4>=1000,5,IF(F4>=500,4,IF(F4>=250,3,IF(F4>=100,2,1)))) | U4: =IFERROR(VLOOKUP(C4,Lookup_Tables!$A$4:$B$8,2,FALSE),3) | V4: =IFERROR(VLOOKUP(H4,Lookup_Tables!$D$4:$E$11,2,FALSE),2) | W4: =IFERROR(VLOOKUP(I4,Lookup_Tables!$D$4:$E$11,2,FALSE),2) | X4: =ROUND((D4*Controls!$B$4)+(G4*Controls!$B$5)+(S4*Controls!$B$6)+(T4*Controls!$B$7)+(U4*Controls!$B$8)+(MAX(V4,W4)*Controls!$B$9),2) | Y4: =IF(AD4="Bulk","A",IF(X4>=Controls!$B$10,"A",IF(X4>=Controls!$B$11,"B","C"))) | Z4: =IF(OR(D4>=4,G4>=4),1,IF(X4>=Controls!$B$11,2,3)) | AA4: =IF(OR(D4>=4,G4>=4),"Front",IF(X4>=Controls!$B$11,"Middle","Back")) | AB4: =IF(P4="Fits",R4,"Manual Review") | AC4: =IF(AD4="Bulk","Bulk / heavy item -> lower level priority",IF(P4<>"Fits","Review cube fit before assigning location",IF(AND(D4>=4,G4>=4),"High usage + high flow -> front-access priority",IF(X4>=Controls!$B$11,"Medium priority item -> standard access","Low priority / reserve storage")))) | AD4: =IF(OR(C4="Bulk",F4>=Controls!$B$12),"Bulk","Non-Bulk") | AE4: High-volume bulk item; lower-level fast-access rule applies. | AF4: =RANK(X4,$X$4:$X$18,0)+COUNTIF($X$4:X4,X4)-1 | AG4: =IFERROR(VLOOKUP(A4,Lookup_Tables!$L$4:$M$18,2,FALSE),"FOOD") | AH4: =IF(AF4<=5,"Premium",IF(AF4<=11,"Standard","Reserve")) | AI4: =IF(AH4="Premium",IF(AG4="GIK","GIK-A"&MOD(AF4-1,3)+1&"-Front",IF(AG4="FOOD","FOOD-A"&MOD(AF4-1,3)+1&"-Front",IF(AG4="ADDITIONS","ADD-A"&MOD(AF4-1,2)+1&"-Front","GAR-A"&MOD(AF4-1,2)+1&"-Front"))),IF(AH4="Standard",IF(AG4="GIK","GIK-B"&MOD(AF4-1,3)+1&"-Middle",IF(AG4="FOOD","FOOD-B"&MOD(AF4-1,3)+1&"-Middle",IF(AG4="ADDITIONS","ADD-B"&MOD(AF4-1,2)+1&"-Middle","GAR-B"&MOD(AF4-1,2)+1&"-Middle"))),IF(AG4="GIK","GIK-C"&MOD(AF4-1,3)+1&"-Back",IF(AG4="FOOD","FOOD-C"&MOD(AF4-1,3)+1&"-Back",IF(AG4="ADDITIONS","ADD-C"&MOD(AF4-1,2)+1&"-Back","GAR-C"&MOD(AF4-1,2)+1&"-Back"))))) | AJ4: =IF(J4=AI4,"Keep in place",IF(LEFT(J4,3)=LEFT(AI4,3),"Re-slot within same zone","Move to "&AG4&" based on flow, capacity, and layout logic")) | AK4: =IF(AH4="Premium",AF4,IF(AH4="Standard",AF4-5,AF4-11)) | AL4: =IF(AH4="Premium",AG4&"-A"&MOD(AK4-1,3)+1&"-Front",IF(AH4="Standard",AG4&"-B"&MOD(AK4-1,3)+1&"-Middle",AG4&"-C"&MOD(AK4-1,3)+1&"-Back")) | AM4: =IF(AH4="Premium","Premium item distributed across A1/A2/A3 by rank to avoid overloading one slot",IF(AH4="Standard","Standard item distributed across B1/B2/B3 by rank","Reserve item distributed across C1/C2/C3 by rank")) | AN4: =MOD(AK4-1,9)+1 | AO4: =IF(AN4=1,AG4&"-A1-Front",IF(AN4=2,AG4&"-B1-Front",IF(AN4=3,AG4&"-C1-Front",IF(AN4=4,AG4&"-A2-Middle",IF(AN4=5,AG4&"-B2-Middle",IF(AN4=6,AG4&"-A3-Back",IF(AN4=7,AG4&"-B3-Back",IF(AN4=8,AG4&"-C2-Middle",AG4&"-C3-Back")))))))) | AP4: =IF(AH4="Premium","Premium item positioned by score rank within premium bucket",IF(AH4="Standard","Standard item positioned by score rank within standard bucket","Reserve item positioned by score rank within reserve bucket"))
A5: Tuna | B5: Food | C5: Food | D5: 5 | E5: 126 | F5: 250 | G5: 5 | H5: Weekly | I5: Daily | J5: B1-Middle | K5: =Controls!$B$22 | L5: =Controls!$B$20 | M5: =Controls!$B$21 | N5: =ROUND(K5*(L5/12)*(M5/12),2) | O5: =IFERROR(VLOOKUP(C5,Lookup_Tables!$G$4:$H$7,2,FALSE),35) | P5: =IF(O5<=N5,"Fits","Review") | Q5: =ROUND(O5/N5,3) | R5: =Y5&Z5&"-"&AA5 | S5: =IF(E5>=1000,5,IF(E5>=500,4,IF(E5>=250,3,IF(E5>=100,2,1)))) | T5: =IF(F5>=1000,5,IF(F5>=500,4,IF(F5>=250,3,IF(F5>=100,2,1)))) | U5: =IFERROR(VLOOKUP(C5,Lookup_Tables!$A$4:$B$8,2,FALSE),3) | V5: =IFERROR(VLOOKUP(H5,Lookup_Tables!$D$4:$E$11,2,FALSE),2) | W5: =IFERROR(VLOOKUP(I5,Lookup_Tables!$D$4:$E$11,2,FALSE),2) | X5: =ROUND((D5*Controls!$B$4)+(G5*Controls!$B$5)+(S5*Controls!$B$6)+(T5*Controls!$B$7)+(U5*Controls!$B$8)+(MAX(V5,W5)*Controls!$B$9),2) | Y5: =IF(AD5="Bulk","A",IF(X5>=Controls!$B$10,"A",IF(X5>=Controls!$B$11,"B","C"))) | Z5: =IF(OR(D5>=4,G5>=4),1,IF(X5>=Controls!$B$11,2,3)) | AA5: =IF(OR(D5>=4,G5>=4),"Front",IF(X5>=Controls!$B$11,"Middle","Back")) | AB5: =IF(P5="Fits",R5,"Manual Review") | AC5: =IF(AD5="Bulk","Bulk / heavy item -> lower level priority",IF(P5<>"Fits","Review cube fit before assigning location",IF(AND(D5>=4,G5>=4),"High usage + high flow -> front-access priority",IF(X5>=Controls!$B$11,"Medium priority item -> standard access","Low priority / reserve storage")))) | AD5: =IF(OR(C5="Bulk",F5>=Controls!$B$12),"Bulk","Non-Bulk") | AF5: =RANK(X5,$X$4:$X$18,0)+COUNTIF($X$4:X5,X5)-1 | AG5: =IFERROR(VLOOKUP(A5,Lookup_Tables!$L$4:$M$18,2,FALSE),"FOOD") | AH5: =IF(AF5<=5,"Premium",IF(AF5<=11,"Standard","Reserve")) | AI5: =IF(AH5="Premium",IF(AG5="GIK","GIK-A"&MOD(AF5-1,3)+1&"-Front",IF(AG5="FOOD","FOOD-A"&MOD(AF5-1,3)+1&"-Front",IF(AG5="ADDITIONS","ADD-A"&MOD(AF5-1,2)+1&"-Front","GAR-A"&MOD(AF5-1,2)+1&"-Front"))),IF(AH5="Standard",IF(AG5="GIK","GIK-B"&MOD(AF5-1,3)+1&"-Middle",IF(AG5="FOOD","FOOD-B"&MOD(AF5-1,3)+1&"-Middle",IF(AG5="ADDITIONS","ADD-B"&MOD(AF5-1,2)+1&"-Middle","GAR-B"&MOD(AF5-1,2)+1&"-Middle"))),IF(AG5="GIK","GIK-C"&MOD(AF5-1,3)+1&"-Back",IF(AG5="FOOD","FOOD-C"&MOD(AF5-1,3)+1&"-Back",IF(AG5="ADDITIONS","ADD-C"&MOD(AF5-1,2)+1&"-Back","GAR-C"&MOD(AF5-1,2)+1&"-Back"))))) | AJ5: =IF(J5=AI5,"Keep in place",IF(LEFT(J5,3)=LEFT(AI5,3),"Re-slot within same zone","Move to "&AG5&" based on flow, capacity, and layout logic")) | AK5: =IF(AH5="Premium",AF5,IF(AH5="Standard",AF5-5,AF5-11)) | AL5: =IF(AH5="Premium",AG5&"-A"&MOD(AK5-1,3)+1&"-Front",IF(AH5="Standard",AG5&"-B"&MOD(AK5-1,3)+1&"-Middle",AG5&"-C"&MOD(AK5-1,3)+1&"-Back")) | AM5: =IF(AH5="Premium","Premium item distributed across A1/A2/A3 by rank to avoid overloading one slot",IF(AH5="Standard","Standard item distributed across B1/B2/B3 by rank","Reserve item distributed across C1/C2/C3 by rank")) | AN5: =MOD(AK5-1,9)+1 | AO5: =IF(AN5=1,AG5&"-A1-Front",IF(AN5=2,AG5&"-B1-Front",IF(AN5=3,AG5&"-C1-Front",IF(AN5=4,AG5&"-A2-Middle",IF(AN5=5,AG5&"-B2-Middle",IF(AN5=6,AG5&"-A3-Back",IF(AN5=7,AG5&"-B3-Back",IF(AN5=8,AG5&"-C2-Middle",AG5&"-C3-Back")))))))) | AP5: =IF(AH5="Premium","Premium item positioned by score rank within premium bucket",IF(AH5="Standard","Standard item positioned by score rank within standard bucket","Reserve item positioned by score rank within reserve bucket"))
A6: Rice | B6: Food | C6: Food | D6: 4 | E6: 115 | F6: 300 | G6: 4 | H6: Weekly | I6: Daily | J6: B2-Middle | K6: =Controls!$B$22 | L6: =Controls!$B$20 | M6: =Controls!$B$21 | N6: =ROUND(K6*(L6/12)*(M6/12),2) | O6: =IFERROR(VLOOKUP(C6,Lookup_Tables!$G$4:$H$7,2,FALSE),35) | P6: =IF(O6<=N6,"Fits","Review") | Q6: =ROUND(O6/N6,3) | R6: =Y6&Z6&"-"&AA6 | S6: =IF(E6>=1000,5,IF(E6>=500,4,IF(E6>=250,3,IF(E6>=100,2,1)))) | T6: =IF(F6>=1000,5,IF(F6>=500,4,IF(F6>=250,3,IF(F6>=100,2,1)))) | U6: =IFERROR(VLOOKUP(C6,Lookup_Tables!$A$4:$B$8,2,FALSE),3) | V6: =IFERROR(VLOOKUP(H6,Lookup_Tables!$D$4:$E$11,2,FALSE),2) | W6: =IFERROR(VLOOKUP(I6,Lookup_Tables!$D$4:$E$11,2,FALSE),2) | X6: =ROUND((D6*Controls!$B$4)+(G6*Controls!$B$5)+(S6*Controls!$B$6)+(T6*Controls!$B$7)+(U6*Controls!$B$8)+(MAX(V6,W6)*Controls!$B$9),2) | Y6: =IF(AD6="Bulk","A",IF(X6>=Controls!$B$10,"A",IF(X6>=Controls!$B$11,"B","C"))) | Z6: =IF(OR(D6>=4,G6>=4),1,IF(X6>=Controls!$B$11,2,3)) | AA6: =IF(OR(D6>=4,G6>=4),"Front",IF(X6>=Controls!$B$11,"Middle","Back")) | AB6: =IF(P6="Fits",R6,"Manual Review") | AC6: =IF(AD6="Bulk","Bulk / heavy item -> lower level priority",IF(P6<>"Fits","Review cube fit before assigning location",IF(AND(D6>=4,G6>=4),"High usage + high flow -> front-access priority",IF(X6>=Controls!$B$11,"Medium priority item -> standard access","Low priority / reserve storage")))) | AD6: =IF(OR(C6="Bulk",F6>=Controls!$B$12),"Bulk","Non-Bulk") | AF6: =RANK(X6,$X$4:$X$18,0)+COUNTIF($X$4:X6,X6)-1 | AG6: =IFERROR(VLOOKUP(A6,Lookup_Tables!$L$4:$M$18,2,FALSE),"FOOD") | AH6: =IF(AF6<=5,"Premium",IF(AF6<=11,"Standard","Reserve")) | AI6: =IF(AH6="Premium",IF(AG6="GIK","GIK-A"&MOD(AF6-1,3)+1&"-Front",IF(AG6="FOOD","FOOD-A"&MOD(AF6-1,3)+1&"-Front",IF(AG6="ADDITIONS","ADD-A"&MOD(AF6-1,2)+1&"-Front","GAR-A"&MOD(AF6-1,2)+1&"-Front"))),IF(AH6="Standard",IF(AG6="GIK","GIK-B"&MOD(AF6-1,3)+1&"-Middle",IF(AG6="FOOD","FOOD-B"&MOD(AF6-1,3)+1&"-Middle",IF(AG6="ADDITIONS","ADD-B"&MOD(AF6-1,2)+1&"-Middle","GAR-B"&MOD(AF6-1,2)+1&"-Middle"))),IF(AG6="GIK","GIK-C"&MOD(AF6-1,3)+1&"-Back",IF(AG6="FOOD","FOOD-C"&MOD(AF6-1,3)+1&"-Back",IF(AG6="ADDITIONS","ADD-C"&MOD(AF6-1,2)+1&"-Back","GAR-C"&MOD(AF6-1,2)+1&"-Back"))))) | AJ6: =IF(J6=AI6,"Keep in place",IF(LEFT(J6,3)=LEFT(AI6,3),"Re-slot within same zone","Move to "&AG6&" based on flow, capacity, and layout logic")) | AK6: =IF(AH6="Premium",AF6,IF(AH6="Standard",AF6-5,AF6-11)) | AL6: =IF(AH6="Premium",AG6&"-A"&MOD(AK6-1,3)+1&"-Front",IF(AH6="Standard",AG6&"-B"&MOD(AK6-1,3)+1&"-Middle",AG6&"-C"&MOD(AK6-1,3)+1&"-Back")) | AM6: =IF(AH6="Premium","Premium item distributed across A1/A2/A3 by rank to avoid overloading one slot",IF(AH6="Standard","Standard item distributed across B1/B2/B3 by rank","Reserve item distributed across C1/C2/C3 by rank")) | AN6: =MOD(AK6-1,9)+1 | AO6: =IF(AN6=1,AG6&"-A1-Front",IF(AN6=2,AG6&"-B1-Front",IF(AN6=3,AG6&"-C1-Front",IF(AN6=4,AG6&"-A2-Middle",IF(AN6=5,AG6&"-B2-Middle",IF(AN6=6,AG6&"-A3-Back",IF(AN6=7,AG6&"-B3-Back",IF(AN6=8,AG6&"-C2-Middle",AG6&"-C3-Back")))))))) | AP6: =IF(AH6="Premium","Premium item positioned by score rank within premium bucket",IF(AH6="Standard","Standard item positioned by score rank within standard bucket","Reserve item positioned by score rank within reserve bucket"))
A7: Black Beans | B7: Food | C7: Food | D7: 4 | E7: 96 | F7: 280 | G7: 4 | H7: Weekly | I7: Daily | J7: B3-Middle | K7: =Controls!$B$22 | L7: =Controls!$B$20 | M7: =Controls!$B$21 | N7: =ROUND(K7*(L7/12)*(M7/12),2) | O7: =IFERROR(VLOOKUP(C7,Lookup_Tables!$G$4:$H$7,2,FALSE),35) | P7: =IF(O7<=N7,"Fits","Review") | Q7: =ROUND(O7/N7,3) | R7: =Y7&Z7&"-"&AA7 | S7: =IF(E7>=1000,5,IF(E7>=500,4,IF(E7>=250,3,IF(E7>=100,2,1)))) | T7: =IF(F7>=1000,5,IF(F7>=500,4,IF(F7>=250,3,IF(F7>=100,2,1)))) | U7: =IFERROR(VLOOKUP(C7,Lookup_Tables!$A$4:$B$8,2,FALSE),3) | V7: =IFERROR(VLOOKUP(H7,Lookup_Tables!$D$4:$E$11,2,FALSE),2) | W7: =IFERROR(VLOOKUP(I7,Lookup_Tables!$D$4:$E$11,2,FALSE),2) | X7: =ROUND((D7*Controls!$B$4)+(G7*Controls!$B$5)+(S7*Controls!$B$6)+(T7*Controls!$B$7)+(U7*Controls!$B$8)+(MAX(V7,W7)*Controls!$B$9),2) | Y7: =IF(AD7="Bulk","A",IF(X7>=Controls!$B$10,"A",IF(X7>=Controls!$B$11,"B","C"))) | Z7: =IF(OR(D7>=4,G7>=4),1,IF(X7>=Controls!$B$11,2,3)) | AA7: =IF(OR(D7>=4,G7>=4),"Front",IF(X7>=Controls!$B$11,"Middle","Back")) | AB7: =IF(P7="Fits",R7,"Manual Review") | AC7: =IF(AD7="Bulk","Bulk / heavy item -> lower level priority",IF(P7<>"Fits","Review cube fit before assigning location",IF(AND(D7>=4,G7>=4),"High usage + high flow -> front-access priority",IF(X7>=Controls!$B$11,"Medium priority item -> standard access","Low priority / reserve storage")))) | AD7: =IF(OR(C7="Bulk",F7>=Controls!$B$12),"Bulk","Non-Bulk") | AF7: =RANK(X7,$X$4:$X$18,0)+COUNTIF($X$4:X7,X7)-1 | AG7: =IFERROR(VLOOKUP(A7,Lookup_Tables!$L$4:$M$18,2,FALSE),"FOOD") | AH7: =IF(AF7<=5,"Premium",IF(AF7<=11,"Standard","Reserve")) | AI7: =IF(AH7="Premium",IF(AG7="GIK","GIK-A"&MOD(AF7-1,3)+1&"-Front",IF(AG7="FOOD","FOOD-A"&MOD(AF7-1,3)+1&"-Front",IF(AG7="ADDITIONS","ADD-A"&MOD(AF7-1,2)+1&"-Front","GAR-A"&MOD(AF7-1,2)+1&"-Front"))),IF(AH7="Standard",IF(AG7="GIK","GIK-B"&MOD(AF7-1,3)+1&"-Middle",IF(AG7="FOOD","FOOD-B"&MOD(AF7-1,3)+1&"-Middle",IF(AG7="ADDITIONS","ADD-B"&MOD(AF7-1,2)+1&"-Middle","GAR-B"&MOD(AF7-1,2)+1&"-Middle"))),IF(AG7="GIK","GIK-C"&MOD(AF7-1,3)+1&"-Back",IF(AG7="FOOD","FOOD-C"&MOD(AF7-1,3)+1&"-Back",IF(AG7="ADDITIONS","ADD-C"&MOD(AF7-1,2)+1&"-Back","GAR-C"&MOD(AF7-1,2)+1&"-Back"))))) | AJ7: =IF(J7=AI7,"Keep in place",IF(LEFT(J7,3)=LEFT(AI7,3),"Re-slot within same zone","Move to "&AG7&" based on flow, capacity, and layout logic")) | AK7: =IF(AH7="Premium",AF7,IF(AH7="Standard",AF7-5,AF7-11)) | AL7: =IF(AH7="Premium",AG7&"-A"&MOD(AK7-1,3)+1&"-Front",IF(AH7="Standard",AG7&"-B"&MOD(AK7-1,3)+1&"-Middle",AG7&"-C"&MOD(AK7-1,3)+1&"-Back")) | AM7: =IF(AH7="Premium","Premium item distributed across A1/A2/A3 by rank to avoid overloading one slot",IF(AH7="Standard","Standard item distributed across B1/B2/B3 by rank","Reserve item distributed across C1/C2/C3 by rank")) | AN7: =MOD(AK7-1,9)+1 | AO7: =IF(AN7=1,AG7&"-A1-Front",IF(AN7=2,AG7&"-B1-Front",IF(AN7=3,AG7&"-C1-Front",IF(AN7=4,AG7&"-A2-Middle",IF(AN7=5,AG7&"-B2-Middle",IF(AN7=6,AG7&"-A3-Back",IF(AN7=7,AG7&"-B3-Back",IF(AN7=8,AG7&"-C2-Middle",AG7&"-C3-Back")))))))) | AP7: =IF(AH7="Premium","Premium item positioned by score rank within premium bucket",IF(AH7="Standard","Standard item positioned by score rank within standard bucket","Reserve item positioned by score rank within reserve bucket"))
A8: Peanut Butter | B8: Food | C8: Bulk | D8: 5 | E8: 135 | F8: 220 | G8: 5 | H8: 4x/Week | I8: 4x/Week | J8: B2-Front | K8: =Controls!$B$22 | L8: =Controls!$B$20 | M8: =Controls!$B$21 | N8: =ROUND(K8*(L8/12)*(M8/12),2) | O8: =IFERROR(VLOOKUP(C8,Lookup_Tables!$G$4:$H$7,2,FALSE),35) | P8: =IF(O8<=N8,"Fits","Review") | Q8: =ROUND(O8/N8,3) | R8: =Y8&Z8&"-"&AA8 | S8: =IF(E8>=1000,5,IF(E8>=500,4,IF(E8>=250,3,IF(E8>=100,2,1)))) | T8: =IF(F8>=1000,5,IF(F8>=500,4,IF(F8>=250,3,IF(F8>=100,2,1)))) | U8: =IFERROR(VLOOKUP(C8,Lookup_Tables!$A$4:$B$8,2,FALSE),3) | V8: =IFERROR(VLOOKUP(H8,Lookup_Tables!$D$4:$E$11,2,FALSE),2) | W8: =IFERROR(VLOOKUP(I8,Lookup_Tables!$D$4:$E$11,2,FALSE),2) | X8: =ROUND((D8*Controls!$B$4)+(G8*Controls!$B$5)+(S8*Controls!$B$6)+(T8*Controls!$B$7)+(U8*Controls!$B$8)+(MAX(V8,W8)*Controls!$B$9),2) | Y8: =IF(AD8="Bulk","A",IF(X8>=Controls!$B$10,"A",IF(X8>=Controls!$B$11,"B","C"))) | Z8: =IF(OR(D8>=4,G8>=4),1,IF(X8>=Controls!$B$11,2,3)) | AA8: =IF(OR(D8>=4,G8>=4),"Front",IF(X8>=Controls!$B$11,"Middle","Back")) | AB8: =IF(P8="Fits",R8,"Manual Review") | AC8: =IF(AD8="Bulk","Bulk / heavy item -> lower level priority",IF(P8<>"Fits","Review cube fit before assigning location",IF(AND(D8>=4,G8>=4),"High usage + high flow -> front-access priority",IF(X8>=Controls!$B$11,"Medium priority item -> standard access","Low priority / reserve storage")))) | AD8: =IF(OR(C8="Bulk",F8>=Controls!$B$12),"Bulk","Non-Bulk") | AE8: Updated from field note: peanut butter arrives in bulk about 4 times per week. | AF8: =RANK(X8,$X$4:$X$18,0)+COUNTIF($X$4:X8,X8)-1 | AG8: =IFERROR(VLOOKUP(A8,Lookup_Tables!$L$4:$M$18,2,FALSE),"FOOD") | AH8: =IF(AF8<=5,"Premium",IF(AF8<=11,"Standard","Reserve")) | AI8: =IF(AH8="Premium",IF(AG8="GIK","GIK-A"&MOD(AF8-1,3)+1&"-Front",IF(AG8="FOOD","FOOD-A"&MOD(AF8-1,3)+1&"-Front",IF(AG8="ADDITIONS","ADD-A"&MOD(AF8-1,2)+1&"-Front","GAR-A"&MOD(AF8-1,2)+1&"-Front"))),IF(AH8="Standard",IF(AG8="GIK","GIK-B"&MOD(AF8-1,3)+1&"-Middle",IF(AG8="FOOD","FOOD-B"&MOD(AF8-1,3)+1&"-Middle",IF(AG8="ADDITIONS","ADD-B"&MOD(AF8-1,2)+1&"-Middle","GAR-B"&MOD(AF8-1,2)+1&"-Middle"))),IF(AG8="GIK","GIK-C"&MOD(AF8-1,3)+1&"-Back",IF(AG8="FOOD","FOOD-C"&MOD(AF8-1,3)+1&"-Back",IF(AG8="ADDITIONS","ADD-C"&MOD(AF8-1,2)+1&"-Back","GAR-C"&MOD(AF8-1,2)+1&"-Back"))))) | AJ8: =IF(J8=AI8,"Keep in place",IF(LEFT(J8,3)=LEFT(AI8,3),"Re-slot within same zone","Move to "&AG8&" based on flow, capacity, and layout logic")) | AK8: =IF(AH8="Premium",AF8,IF(AH8="Standard",AF8-5,AF8-11)) | AL8: =IF(AH8="Premium",AG8&"-A"&MOD(AK8-1,3)+1&"-Front",IF(AH8="Standard",AG8&"-B"&MOD(AK8-1,3)+1&"-Middle",AG8&"-C"&MOD(AK8-1,3)+1&"-Back")) | AM8: =IF(AH8="Premium","Premium item distributed across A1/A2/A3 by rank to avoid overloading one slot",IF(AH8="Standard","Standard item distributed across B1/B2/B3 by rank","Reserve item distributed across C1/C2/C3 by rank")) | AN8: =MOD(AK8-1,9)+1 | AO8: =IF(AN8=1,AG8&"-A1-Front",IF(AN8=2,AG8&"-B1-Front",IF(AN8=3,AG8&"-C1-Front",IF(AN8=4,AG8&"-A2-Middle",IF(AN8=5,AG8&"-B2-Middle",IF(AN8=6,AG8&"-A3-Back",IF(AN8=7,AG8&"-B3-Back",IF(AN8=8,AG8&"-C2-Middle",AG8&"-C3-Back")))))))) | AP8: =IF(AH8="Premium","Premium item positioned by score rank within premium bucket",IF(AH8="Standard","Standard item positioned by score rank within standard bucket","Reserve item positioned by score rank within reserve bucket"))
A9: Pasta Sauce | B9: Food | C9: Food | D9: 3 | E9: 96 | F9: 180 | G9: 3 | H9: Weekly | I9: Weekly | J9: C1-Middle | K9: =Controls!$B$22 | L9: =Controls!$B$20 | M9: =Controls!$B$21 | N9: =ROUND(K9*(L9/12)*(M9/12),2) | O9: =IFERROR(VLOOKUP(C9,Lookup_Tables!$G$4:$H$7,2,FALSE),35) | P9: =IF(O9<=N9,"Fits","Review") | Q9: =ROUND(O9/N9,3) | R9: =Y9&Z9&"-"&AA9 | S9: =IF(E9>=1000,5,IF(E9>=500,4,IF(E9>=250,3,IF(E9>=100,2,1)))) | T9: =IF(F9>=1000,5,IF(F9>=500,4,IF(F9>=250,3,IF(F9>=100,2,1)))) | U9: =IFERROR(VLOOKUP(C9,Lookup_Tables!$A$4:$B$8,2,FALSE),3) | V9: =IFERROR(VLOOKUP(H9,Lookup_Tables!$D$4:$E$11,2,FALSE),2) | W9: =IFERROR(VLOOKUP(I9,Lookup_Tables!$D$4:$E$11,2,FALSE),2) | X9: =ROUND((D9*Controls!$B$4)+(G9*Controls!$B$5)+(S9*Controls!$B$6)+(T9*Controls!$B$7)+(U9*Controls!$B$8)+(MAX(V9,W9)*Controls!$B$9),2) | Y9: =IF(AD9="Bulk","A",IF(X9>=Controls!$B$10,"A",IF(X9>=Controls!$B$11,"B","C"))) | Z9: =IF(OR(D9>=4,G9>=4),1,IF(X9>=Controls!$B$11,2,3)) | AA9: =IF(OR(D9>=4,G9>=4),"Front",IF(X9>=Controls!$B$11,"Middle","Back")) | AB9: =IF(P9="Fits",R9,"Manual Review") | AC9: =IF(AD9="Bulk","Bulk / heavy item -> lower level priority",IF(P9<>"Fits","Review cube fit before assigning location",IF(AND(D9>=4,G9>=4),"High usage + high flow -> front-access priority",IF(X9>=Controls!$B$11,"Medium priority item -> standard access","Low priority / reserve storage")))) | AD9: =IF(OR(C9="Bulk",F9>=Controls!$B$12),"Bulk","Non-Bulk") | AF9: =RANK(X9,$X$4:$X$18,0)+COUNTIF($X$4:X9,X9)-1 | AG9: =IFERROR(VLOOKUP(A9,Lookup_Tables!$L$4:$M$18,2,FALSE),"FOOD") | AH9: =IF(AF9<=5,"Premium",IF(AF9<=11,"Standard","Reserve")) | AI9: =IF(AH9="Premium",IF(AG9="GIK","GIK-A"&MOD(AF9-1,3)+1&"-Front",IF(AG9="FOOD","FOOD-A"&MOD(AF9-1,3)+1&"-Front",IF(AG9="ADDITIONS","ADD-A"&MOD(AF9-1,2)+1&"-Front","GAR-A"&MOD(AF9-1,2)+1&"-Front"))),IF(AH9="Standard",IF(AG9="GIK","GIK-B"&MOD(AF9-1,3)+1&"-Middle",IF(AG9="FOOD","FOOD-B"&MOD(AF9-1,3)+1&"-Middle",IF(AG9="ADDITIONS","ADD-B"&MOD(AF9-1,2)+1&"-Middle","GAR-B"&MOD(AF9-1,2)+1&"-Middle"))),IF(AG9="GIK","GIK-C"&MOD(AF9-1,3)+1&"-Back",IF(AG9="FOOD","FOOD-C"&MOD(AF9-1,3)+1&"-Back",IF(AG9="ADDITIONS","ADD-C"&MOD(AF9-1,2)+1&"-Back","GAR-C"&MOD(AF9-1,2)+1&"-Back"))))) | AJ9: =IF(J9=AI9,"Keep in place",IF(LEFT(J9,3)=LEFT(AI9,3),"Re-slot within same zone","Move to "&AG9&" based on flow, capacity, and layout logic")) | AK9: =IF(AH9="Premium",AF9,IF(AH9="Standard",AF9-5,AF9-11)) | AL9: =IF(AH9="Premium",AG9&"-A"&MOD(AK9-1,3)+1&"-Front",IF(AH9="Standard",AG9&"-B"&MOD(AK9-1,3)+1&"-Middle",AG9&"-C"&MOD(AK9-1,3)+1&"-Back")) | AM9: =IF(AH9="Premium","Premium item distributed across A1/A2/A3 by rank to avoid overloading one slot",IF(AH9="Standard","Standard item distributed across B1/B2/B3 by rank","Reserve item distributed across C1/C2/C3 by rank")) | AN9: =MOD(AK9-1,9)+1 | AO9: =IF(AN9=1,AG9&"-A1-Front",IF(AN9=2,AG9&"-B1-Front",IF(AN9=3,AG9&"-C1-Front",IF(AN9=4,AG9&"-A2-Middle",IF(AN9=5,AG9&"-B2-Middle",IF(AN9=6,AG9&"-A3-Back",IF(AN9=7,AG9&"-B3-Back",IF(AN9=8,AG9&"-C2-Middle",AG9&"-C3-Back")))))))) | AP9: =IF(AH9="Premium","Premium item positioned by score rank within premium bucket",IF(AH9="Standard","Standard item positioned by score rank within standard bucket","Reserve item positioned by score rank within reserve bucket"))
A10: Oats | B10: Food | C10: Food | D10: 3 | E10: 150 | F10: 160 | G10: 3 | H10: Weekly | I10: Weekly | J10: C2-Middle | K10: =Controls!$B$22 | L10: =Controls!$B$20 | M10: =Controls!$B$21 | N10: =ROUND(K10*(L10/12)*(M10/12),2) | O10: =IFERROR(VLOOKUP(C10,Lookup_Tables!$G$4:$H$7,2,FALSE),35) | P10: =IF(O10<=N10,"Fits","Review") | Q10: =ROUND(O10/N10,3) | R10: =Y10&Z10&"-"&AA10 | S10: =IF(E10>=1000,5,IF(E10>=500,4,IF(E10>=250,3,IF(E10>=100,2,1)))) | T10: =IF(F10>=1000,5,IF(F10>=500,4,IF(F10>=250,3,IF(F10>=100,2,1)))) | U10: =IFERROR(VLOOKUP(C10,Lookup_Tables!$A$4:$B$8,2,FALSE),3) | V10: =IFERROR(VLOOKUP(H10,Lookup_Tables!$D$4:$E$11,2,FALSE),2) | W10: =IFERROR(VLOOKUP(I10,Lookup_Tables!$D$4:$E$11,2,FALSE),2) | X10: =ROUND((D10*Controls!$B$4)+(G10*Controls!$B$5)+(S10*Controls!$B$6)+(T10*Controls!$B$7)+(U10*Controls!$B$8)+(MAX(V10,W10)*Controls!$B$9),2) | Y10: =IF(AD10="Bulk","A",IF(X10>=Controls!$B$10,"A",IF(X10>=Controls!$B$11,"B","C"))) | Z10: =IF(OR(D10>=4,G10>=4),1,IF(X10>=Controls!$B$11,2,3)) | AA10: =IF(OR(D10>=4,G10>=4),"Front",IF(X10>=Controls!$B$11,"Middle","Back")) | AB10: =IF(P10="Fits",R10,"Manual Review") | AC10: =IF(AD10="Bulk","Bulk / heavy item -> lower level priority",IF(P10<>"Fits","Review cube fit before assigning location",IF(AND(D10>=4,G10>=4),"High usage + high flow -> front-access priority",IF(X10>=Controls!$B$11,"Medium priority item -> standard access","Low priority / reserve storage")))) | AD10: =IF(OR(C10="Bulk",F10>=Controls!$B$12),"Bulk","Non-Bulk") | AF10: =RANK(X10,$X$4:$X$18,0)+COUNTIF($X$4:X10,X10)-1 | AG10: =IFERROR(VLOOKUP(A10,Lookup_Tables!$L$4:$M$18,2,FALSE),"FOOD") | AH10: =IF(AF10<=5,"Premium",IF(AF10<=11,"Standard","Reserve")) | AI10: =IF(AH10="Premium",IF(AG10="GIK","GIK-A"&MOD(AF10-1,3)+1&"-Front",IF(AG10="FOOD","FOOD-A"&MOD(AF10-1,3)+1&"-Front",IF(AG10="ADDITIONS","ADD-A"&MOD(AF10-1,2)+1&"-Front","GAR-A"&MOD(AF10-1,2)+1&"-Front"))),IF(AH10="Standard",IF(AG10="GIK","GIK-B"&MOD(AF10-1,3)+1&"-Middle",IF(AG10="FOOD","FOOD-B"&MOD(AF10-1,3)+1&"-Middle",IF(AG10="ADDITIONS","ADD-B"&MOD(AF10-1,2)+1&"-Middle","GAR-B"&MOD(AF10-1,2)+1&"-Middle"))),IF(AG10="GIK","GIK-C"&MOD(AF10-1,3)+1&"-Back",IF(AG10="FOOD","FOOD-C"&MOD(AF10-1,3)+1&"-Back",IF(AG10="ADDITIONS","ADD-C"&MOD(AF10-1,2)+1&"-Back","GAR-C"&MOD(AF10-1,2)+1&"-Back"))))) | AJ10: =IF(J10=AI10,"Keep in place",IF(LEFT(J10,3)=LEFT(AI10,3),"Re-slot within same zone","Move to "&AG10&" based on flow, capacity, and layout logic")) | AK10: =IF(AH10="Premium",AF10,IF(AH10="Standard",AF10-5,AF10-11)) | AL10: =IF(AH10="Premium",AG10&"-A"&MOD(AK10-1,3)+1&"-Front",IF(AH10="Standard",AG10&"-B"&MOD(AK10-1,3)+1&"-Middle",AG10&"-C"&MOD(AK10-1,3)+1&"-Back")) | AM10: =IF(AH10="Premium","Premium item distributed across A1/A2/A3 by rank to avoid overloading one slot",IF(AH10="Standard","Standard item distributed across B1/B2/B3 by rank","Reserve item distributed across C1/C2/C3 by rank")) | AN10: =MOD(AK10-1,9)+1 | AO10: =IF(AN10=1,AG10&"-A1-Front",IF(AN10=2,AG10&"-B1-Front",IF(AN10=3,AG10&"-C1-Front",IF(AN10=4,AG10&"-A2-Middle",IF(AN10=5,AG10&"-B2-Middle",IF(AN10=6,AG10&"-A3-Back",IF(AN10=7,AG10&"-B3-Back",IF(AN10=8,AG10&"-C2-Middle",AG10&"-C3-Back")))))))) | AP10: =IF(AH10="Premium","Premium item positioned by score rank within premium bucket",IF(AH10="Standard","Standard item positioned by score rank within standard bucket","Reserve item positioned by score rank within reserve bucket"))
A11: Pancake Mix | B11: Food | C11: Food | D11: 3 | E11: 105 | F11: 140 | G11: 3 | H11: Weekly | I11: Weekly | J11: C2-Back | K11: =Controls!$B$22 | L11: =Controls!$B$20 | M11: =Controls!$B$21 | N11: =ROUND(K11*(L11/12)*(M11/12),2) | O11: =IFERROR(VLOOKUP(C11,Lookup_Tables!$G$4:$H$7,2,FALSE),35) | P11: =IF(O11<=N11,"Fits","Review") | Q11: =ROUND(O11/N11,3) | R11: =Y11&Z11&"-"&AA11 | S11: =IF(E11>=1000,5,IF(E11>=500,4,IF(E11>=250,3,IF(E11>=100,2,1)))) | T11: =IF(F11>=1000,5,IF(F11>=500,4,IF(F11>=250,3,IF(F11>=100,2,1)))) | U11: =IFERROR(VLOOKUP(C11,Lookup_Tables!$A$4:$B$8,2,FALSE),3) | V11: =IFERROR(VLOOKUP(H11,Lookup_Tables!$D$4:$E$11,2,FALSE),2) | W11: =IFERROR(VLOOKUP(I11,Lookup_Tables!$D$4:$E$11,2,FALSE),2) | X11: =ROUND((D11*Controls!$B$4)+(G11*Controls!$B$5)+(S11*Controls!$B$6)+(T11*Controls!$B$7)+(U11*Controls!$B$8)+(MAX(V11,W11)*Controls!$B$9),2) | Y11: =IF(AD11="Bulk","A",IF(X11>=Controls!$B$10,"A",IF(X11>=Controls!$B$11,"B","C"))) | Z11: =IF(OR(D11>=4,G11>=4),1,IF(X11>=Controls!$B$11,2,3)) | AA11: =IF(OR(D11>=4,G11>=4),"Front",IF(X11>=Controls!$B$11,"Middle","Back")) | AB11: =IF(P11="Fits",R11,"Manual Review") | AC11: =IF(AD11="Bulk","Bulk / heavy item -> lower level priority",IF(P11<>"Fits","Review cube fit before assigning location",IF(AND(D11>=4,G11>=4),"High usage + high flow -> front-access priority",IF(X11>=Controls!$B$11,"Medium priority item -> standard access","Low priority / reserve storage")))) | AD11: =IF(OR(C11="Bulk",F11>=Controls!$B$12),"Bulk","Non-Bulk") | AF11: =RANK(X11,$X$4:$X$18,0)+COUNTIF($X$4:X11,X11)-1 | AG11: =IFERROR(VLOOKUP(A11,Lookup_Tables!$L$4:$M$18,2,FALSE),"FOOD") | AH11: =IF(AF11<=5,"Premium",IF(AF11<=11,"Standard","Reserve")) | AI11: =IF(AH11="Premium",IF(AG11="GIK","GIK-A"&MOD(AF11-1,3)+1&"-Front",IF(AG11="FOOD","FOOD-A"&MOD(AF11-1,3)+1&"-Front",IF(AG11="ADDITIONS","ADD-A"&MOD(AF11-1,2)+1&"-Front","GAR-A"&MOD(AF11-1,2)+1&"-Front"))),IF(AH11="Standard",IF(AG11="GIK","GIK-B"&MOD(AF11-1,3)+1&"-Middle",IF(AG11="FOOD","FOOD-B"&MOD(AF11-1,3)+1&"-Middle",IF(AG11="ADDITIONS","ADD-B"&MOD(AF11-1,2)+1&"-Middle","GAR-B"&MOD(AF11-1,2)+1&"-Middle"))),IF(AG11="GIK","GIK-C"&MOD(AF11-1,3)+1&"-Back",IF(AG11="FOOD","FOOD-C"&MOD(AF11-1,3)+1&"-Back",IF(AG11="ADDITIONS","ADD-C"&MOD(AF11-1,2)+1&"-Back","GAR-C"&MOD(AF11-1,2)+1&"-Back"))))) | AJ11: =IF(J11=AI11,"Keep in place",IF(LEFT(J11,3)=LEFT(AI11,3),"Re-slot within same zone","Move to "&AG11&" based on flow, capacity, and layout logic")) | AK11: =IF(AH11="Premium",AF11,IF(AH11="Standard",AF11-5,AF11-11)) | AL11: =IF(AH11="Premium",AG11&"-A"&MOD(AK11-1,3)+1&"-Front",IF(AH11="Standard",AG11&"-B"&MOD(AK11-1,3)+1&"-Middle",AG11&"-C"&MOD(AK11-1,3)+1&"-Back")) | AM11: =IF(AH11="Premium","Premium item distributed across A1/A2/A3 by rank to avoid overloading one slot",IF(AH11="Standard","Standard item distributed across B1/B2/B3 by rank","Reserve item distributed across C1/C2/C3 by rank")) | AN11: =MOD(AK11-1,9)+1 | AO11: =IF(AN11=1,AG11&"-A1-Front",IF(AN11=2,AG11&"-B1-Front",IF(AN11=3,AG11&"-C1-Front",IF(AN11=4,AG11&"-A2-Middle",IF(AN11=5,AG11&"-B2-Middle",IF(AN11=6,AG11&"-A3-Back",IF(AN11=7,AG11&"-B3-Back",IF(AN11=8,AG11&"-C2-Middle",AG11&"-C3-Back")))))))) | AP11: =IF(AH11="Premium","Premium item positioned by score rank within premium bucket",IF(AH11="Standard","Standard item positioned by score rank within standard bucket","Reserve item positioned by score rank within reserve bucket"))
